Workbook
Name AKAADDR1: [1]RENTROLL!#REF!
Name appraised: [1]SETUP!#REF!
Name APT: [1]RENTROLL!$A$83
Name COMMRENT: [1]RENTROLL!$G$93
Name File: [1]RENTROLL!$M$1
Name masterblock: [1]RENTROLL!$M$2
Name masterlot: [1]RENTROLL!$M$3
Name PROPERTY: [1]RENTROLL!$H$1
Name RENT: #REF!
Name ROOMS: [1]RENTROLL!$E$83

Sheet Cover
B2: 33-35 W. 125TH STREET

Sheet Summary
B2: 33-35 W. 125th Street
B3: Irgang Group
B5: Project Summary | J5: Proforma Valuation Summary
B6: Project Name | H6: =B2 -> 33-35 W. 125th Street | J6: Proforma NOI (Abated) | N6: ='Proforma I&E'!O4 -> 7756288.9
B7: Address/Location | H7: 33-35 W 125th St, New York, NY 10027 | J7: Proforma NOI (Full Tax) | N7: ='Proforma I&E'!O5 -> 6021503.1
B8: Submarket | H8: Harlem | J8: Cap Rate | N8: ='Proforma I&E'!O6 -> 0.0575
B9: Sponsor | H9: =B3 -> Irgang Group | J9: Full Tax Value (A): | N9: =N7/N8 -> 1.0472179e+08
B10: Block / Lot | H10: 1723 / 17 | J10: PV of Tax Savings (B): | N10: ='Proforma I&E'!O8 -> 45664817
J11: Total Stabilized Value (A + B): | N11: =SUM(N9:N10) -> 1.5038661e+08
B12: Lot SF | H12: 11990 | J12: Value / Unit | N12: =N11/Summary!$H$18 -> 835481.16
B13: FAR | H13: 12 | J13: Value / GSF | N13: =N11/Summary!$H$15 -> 870.08467
B14: ZFA | H14: =H12*H13 -> 143880
B15: GSF | H15: 172841.35 | J15: Development Capitalization | N15: =D34 -> 98550528
B16: NSF | H16: =SUM(H19,H21) -> 137955 | J16: Construction Loan | N16: =D25 -> 70000000
J17: Debt / Unit | N17: =N16/Summary!$H$18 -> 388888.89
B18: Total Residential Units | H18: ='Unit Mix & RR'!I25 -> 180 | J18: Debt / GSF | N18: =N16/Summary!$H$15 -> 404.99568
B19: Total Residential SF | H19: ='Unit Mix & RR'!J25 -> 120516
B20: Total Commercial Units | H20: 2 | J20: Stabilized LTV | N20: =N16/N11 -> 0.46546698
B21: Total Commercial SF | H21: ='Unit Mix & RR'!R8 -> 17439 | J21: Stabilized DY | N21: =N6/N16 -> 0.11080413
J22: Stabilized YoC | N22: =N6/N15 -> 0.078703677
B23: Sources & Uses
B24: Sources | D24: Total Cost | E24: $ / ZFA | F24: $ / GSF | G24: $ / Unit | H24: %
B25: Senior Loan | D25: ='Development Budget'!O8 -> 70000000 | E25: =D25/$H$14 -> 486.51654 | F25: =D25/$H$15 -> 404.99568 | G25: =D25/$H$18 -> 388888.89 | H25: =D25/$D$27 -> 0.71029553
B26: Sponsor Equity | D26: =D34-D25 -> 28550528 | E26: =D26/$H$14 -> 198.43292 | F26: =D26/$H$15 -> 165.18344 | G26: =D26/$H$18 -> 158614.04 | H26: =D26/$D$27 -> 0.28970447
B27: Total Sources: | D27: =SUM(D25:D26) -> 98550528 | E27: =D27/$H$14 -> 684.94946 | F27: =D27/$H$15 -> 570.17912 | G27: =D27/$H$18 -> 547502.93 | H27: =D27/$D$27 -> 1
B28: Uses | D28: Total Cost | E28: $ / ZFA | F28: $ / GSF | G28: $ / Unit | H28: %
B29: Acquisition Costs | D29: ='Development Budget'!O12 -> 25179000 | E29: =D29/$H$14 -> 175 | F29: =D29/$H$15 -> 145.67695 | G29: =D29/$H$18 -> 139883.33 | H29: =D29/$D$34 -> 0.2554933
B30: Hard Costs | D30: ='Development Budget'!O13 -> 53742128 | E30: =D30/$H$14 -> 373.52049 | F30: =D30/$H$15 -> 310.93328 | G30: =D30/$H$18 -> 298567.38 | H30: =D30/$D$34 -> 0.54532562
B31: Soft Costs | D31: ='Development Budget'!O14 -> 6000000 | E31: =D31/$H$14 -> 41.701418 | F31: =D31/$H$15 -> 34.713915 | G31: =D31/$H$18 -> 33333.333 | H31: =D31/$D$34 -> 0.060882474
B32: Financing Costs | D32: ='Development Budget'!O15 -> 3619400 | E32: =D32/$H$14 -> 25.155685 | F32: =D32/$H$15 -> 20.940591 | G32: =D32/$H$18 -> 20107.778 | H32: =D32/$D$34 -> 0.036726338
B33: Interest/Carry Costs | D33: ='Development Budget'!O16 -> 10010000 | E33: =D33/$H$14 -> 69.571865 | F33: =D33/$H$15 -> 57.914382 | G33: =D33/$H$18 -> 55611.111 | H33: =D33/$D$34 -> 0.10157226
B34: Total Uses: | D34: =SUM(D29:D33) -> 98550528 | E34: =D34/$H$14 -> 684.94946 | F34: =D34/$H$15 -> 570.17912 | G34: =D34/$H$18 -> 547502.93 | H34: =D34/$D$34 -> 1

Sheet Proforma I&E
B3: RENTAL PROFORMA | K3: Valuation Summary
B4: Income: | F4: $ Total | G4: $ / Unit | H4: $ / GSF | I4: % EGI | K4: Proforma NOI (Abated) | O4: =F26 -> 7756288.9
B5: Residential Income (FM) | D5: Rent Roll | F5: ='Unit Mix & RR'!M9 -> 7170685 | G5: =F5/Summary!$H$18 -> 39837.139 | H5: =F5/Summary!$H$15 -> 41.487092 | I5: =F5/$F$11 -> 0.77352096 | K5: Proforma NOI (Full Tax) | O5: =F26-F15 -> 6021503.1
B6: Vacancy & Credit Loss (FM) | D6: -0.05 | F6: =D6*F5 -> -358534.25 | G6: =F6/Summary!$H$18 -> -1991.8569 | H6: =F6/Summary!$H$15 -> -2.0743546 | I6: =F6/$F$11 -> -0.038676048 | K6: Cap Rate | O6: 0.0575
B7: Residential Income (HPD / IH) | D7: Rent Roll | F7: ='Unit Mix & RR'!M17 -> 1397760 | G7: =F7/Summary!$H$18 -> 7765.3333 | H7: =F7/Summary!$H$15 -> 8.0869537 | I7: =F7/$F$11 -> 0.15078011 | K7: Full Tax Value (A): | O7: =O5/O6 -> 1.0472179e+08
B8: Vacancy & Credit Loss (HPD / IH) | D8: -0.02 | F8: =D8*F7 -> -27955.2 | G8: =F8/Summary!$H$18 -> -155.30667 | H8: =F8/Summary!$H$15 -> -0.16173907 | I8: =F8/$F$11 -> -0.0030156022 | K8: PV of Tax Savings (B): | O8: ='421(a) Abatement'!E9 -> 45664817
B9: Commercial Income | D9: Rent Roll | F9: ='Unit Mix & RR'!T8 -> 1017040 | G9: =F9/Summary!$H$18 -> 5650.2222 | H9: =F9/Summary!$H$15 -> 5.8842401 | I9: =F9/$F$11 -> 0.10971082 | K9: Total Stabilized Value (A + B): | O9: =SUM(O7:O8) -> 1.5038661e+08
B10: Vacancy & Credit Loss (Commercial) | D10: 0.07 | F10: =D10*SUM(F9:F9) -> 71192.8 | G10: =F10/Summary!$H$18 -> 395.51556 | H10: =F10/Summary!$H$15 -> 0.41189681 | I10: =F10/$F$11 -> 0.0076797577 | K10: Value / Unit | O10: =O9/Summary!$H$18 -> 835481.16
B11: Effective Gross Income | F11: =SUM(F5:F10) -> 9270188.4 | G11: =F11/Summary!$H$18 -> 51501.046 | H11: =F11/Summary!$H$15 -> 53.634089 | I11: =F11/$F$11 -> 1 | K11: Value / GSF | O11: =O9/Summary!$H$15 -> 870.08467
B13: Expenses: | F13: $ Total | G13: $ / Unit | H13: $ / GSF | I13: % EGI | K13: Development Capitalization | O13: ='Development Budget'!D88 -> 98550528
B14: Real Estate Taxes | D14: 421A Analysis | F14: =-'421(a) Abatement'!C23 -> -1995912.1 | G14: =F14/Summary!$H$18 -> -11088.401 | H14: =F14/Summary!$H$15 -> -11.547654 | I14: =F14/$F$11 -> -0.21530438 | K14: Construction Loan | O14: ='Development Budget'!O8 -> 70000000
B15: Real Estate Taxes Savings | D15: 421A Analysis | F15: ='421(a) Abatement'!C25 -> 1734785.9 | G15: =F15/Summary!$H$18 -> 9637.6993 | H15: =F15/Summary!$H$15 -> 10.036868 | I15: =F15/$F$11 -> 0.18713599 | K15: Debt / Unit | O15: =O14/Summary!$H$18 -> 388888.89
B16: Insurance | D16: Sponsor Budget | F16: =G16*Summary!$H$18 -> -180000 | G16: -1000 | H16: =F16/Summary!$H$15 -> -1.0414175 | I16: =F16/$F$11 -> -0.019417081 | K16: Debt / GSF | O16: =O14/Summary!$H$15 -> 404.99568
B17: Water/Sewer | D17: Sponsor Budget | F17: =G17*Summary!$H$18 -> -99000 | G17: -550 | H17: =F17/Summary!$H$15 -> -0.5727796 | I17: =F17/$F$11 -> -0.010679395
B18: Utilities | D18: Sponsor Budget | F18: =G18*Summary!$H$18 -> -135000 | G18: -750 | H18: =F18/Summary!$H$15 -> -0.7810631 | I18: =F18/$F$11 -> -0.014562811 | K18: Stabilized LTV | O18: =O14/$O$9 -> 0.46546698
B19: Repairs & Maintenance | D19: Sponsor Budget | F19: =G19*Summary!$H$18 -> -90000 | G19: -500 | H19: =F19/Summary!$H$15 -> -0.52070873 | I19: =F19/$F$11 -> -0.0097085406 | K19: Stabilized DY | O19: =$O$4/$O$14 -> 0.11080413
B20: Payroll | D20: Sponsor Budget | F20: =G20*Summary!$H$18 -> -384267.52 | G20: -2134.8196 | H20: =F20/Summary!$H$15 -> -2.2232384 | I20: =F20/$F$11 -> -0.041451965 | K20: Stabilized YoC | O20: =$O$4/$O$13 -> 0.078703677
B21: General & Administrative | D21: Sponsor Budget | F21: =G21*Summary!$H$18 -> -41400 | G21: -230 | H21: =F21/Summary!$H$15 -> -0.23952602 | I21: =F21/$F$11 -> -0.0044659287
B22: Management Fee | D22: Mgmt Fee | F22: =I22*$F$11 -> -278105.65 | G22: =F22/Summary!$H$18 -> -1545.0314 | H22: =F22/Summary!$H$15 -> -1.6090227 | I22: -0.03
B23: Reserves | D23: Reserves | F23: =G23*Summary!$H$18 -> -45000 | G23: -250 | H23: =F23/Summary!$H$15 -> -0.26035437 | I23: =F23/$F$11 -> -0.0048542703
B24: Total Expenses | F24: =SUM(F14:F23) -> -1513899.4 | G24: =F24/Summary!$H$18 -> -8410.5523 | H24: =F24/Summary!$H$15 -> -8.7588961 | I24: =F24/$F$11 -> -0.16330838
B26: Net Operating Income | F26: =SUM(F24,F11) -> 7756288.9 | G26: =F26/Summary!$H$18 -> 43090.494 | H26: =F26/Summary!$H$15 -> 44.875193 | I26: =F26/$F$11 -> 0.83669162

Sheet Unit Mix & RR
B3: RESIDENTIAL RENT ROLL | H3: Unit Mix Summary | J3: FM | Q3: COMMERCIAL RENT ROLL
E4: Square | I4: Total | J4: Total | K4: Avg. | L4: Total | M4: Total | N4: Avg. Rent | O4: Avg. Rent | R4: Square | S4: Monthly | T4: Annual | U4: Rent
B5: Floor | C5: Unit | D5: Bed | E5: Feet | H5: Bed | I5: Units | J5: SqFt | K5: SqFt | L5: Rent/Mo. | M5: Rent/Yr. | N5: ($ /Unit) | O5: ($ / SqFt) | Q5: Unit | R5: Feet | S5: Rent | T5: Rent | U5: ($ / SF)
B6: 2 | C6: 201 | D6: 2 | E6: 856 | H6: 0 | I6: =I22-I14 -> 18 | J6: =J22-J14 -> 8644 | K6: =J6/I6 -> 480.22222 | L6: =M6/12 -> 61228.333 | M6: =O6*J6 -> 734740 | N6: =L6/I6 -> 3401.5741 | O6: 85 | Q6: Gallery | R6: 8311 | S6: =T6/12 -> 27703.333 | T6: =U6*R6 -> 332440 | U6: 40
B7: 2 | C7: 202 | D7: 2 | E7: 659 | H7: 1 | I7: =I23-I15 -> 56 | J7: =J23-J15 -> 35048 | K7: =J7/I7 -> 625.85714 | L7: =M7/12 -> 248256.67 | M7: =O7*J7 -> 2979080 | N7: =L7/I7 -> 4433.1548 | O7: 85 | Q7: Retail | R7: 9128 | S7: =T7/12 -> 57050 | T7: =U7*R7 -> 684600 | U7: 75
B8: 2 | C8: 203 | D8: 2 | E8: 856 | H8: 2 | I8: =I24-I16 -> 52 | J8: =J24-J16 -> 40669 | K8: =J8/I8 -> 782.09615 | L8: =M8/12 -> 288072.08 | M8: =O8*J8 -> 3456865 | N8: =L8/I8 -> 5539.8478 | O8: 85 | Q8: TOTAL / AVG: | R8: =SUM(R6:R7) -> 17439 | S8: =SUM(S6:S7) -> 84753.333 | T8: =SUM(T6:T7) -> 1017040 | U8: =T8/R8 -> 58.319858
B9: 2 | C9: 204 | D9: 1 | E9: 556 | H9: TOTAL / AVG: | I9: =SUM(I6:I8) -> 126 | J9: =SUM(J6:J8) -> 84361 | K9: =J9/I9 -> 669.53175 | L9: =SUM(L6:L8) -> 597557.08 | M9: =SUM(M6:M8) -> 7170685 | N9: =L9/I9 -> 4742.5165 | O9: =N9/K9*12 -> 85
B10: 2 | C10: 205 | D10: 1 | E10: 680
B11: 3 | C11: 301 | D11: 2 | E11: 868 | H11: Unit Mix Summary | J11: HPD / IH
B12: 3 | C12: 302 | D12: 2 | E12: 646 | I12: Total | J12: Total | K12: Avg. | L12: Total | M12: Total | N12: Avg. Rent | O12: Avg. Rent
B13: 3 | C13: 303 | D13: 2 | E13: 800 | H13: Bed | I13: Units | J13: SqFt | K13: SqFt | L13: Rent/Mo. | M13: Rent/Yr. | N13: ($ /Unit) | O13: ($ / SqFt)
B14: 3 | C14: 304 | D14: 1 | E14: 611 | G14: 0.3 | H14: 0 | I14: =ROUND($G14*I22,0) -> 8 | J14: =ROUND($G14*J22,0) -> 3705 | K14: =J14/I14 -> 463.125 | L14: =N14*I14 -> 13040 | M14: =L14*12 -> 156480 | N14: 1630 | O14: =N14/K14*12 -> 42.234818
B15: 3 | C15: 305 | D15: 1 | E15: 680 | G15: 0.3 | H15: 1 | I15: =ROUND($G15*I23,0) -> 24 | J15: =ROUND($G15*J23,0) -> 15020 | K15: =J15/I15 -> 625.83333 | L15: =N15*I15 -> 41928 | M15: =L15*12 -> 503136 | N15: 1747 | O15: =N15/K15*12 -> 33.497736
B16: 3 | C16: 306 | D16: 0 | E16: 458 | G16: 0.3 | H16: 2 | I16: =ROUND($G16*I24,0) -> 22 | J16: =ROUND($G16*J24,0) -> 17430 | K16: =J16/I16 -> 792.27273 | L16: =N16*I16 -> 61512 | M16: =L16*12 -> 738144 | N16: 2796 | O16: =N16/K16*12 -> 42.349053
B17: 3 | C17: 307 | D17: 0 | E17: 468 | H17: TOTAL / AVG: | I17: =SUM(I14:I16) -> 54 | J17: =SUM(J14:J16) -> 36155 | K17: =J17/I17 -> 669.53704 | L17: =SUM(L14:L16) -> 116480 | M17: =SUM(M14:M16) -> 1397760 | N17: =L17/I17 -> 2157.037 | O17: =N17/K17*12 -> 38.660213
B18: 3 | C18: 308 | D18: 1 | E18: 654
B19: 3 | C19: 309 | D19: 1 | E19: 616 | H19: Unit Mix Summary | J19: TOTAL
B20: 3 | C20: 310 | D20: 1 | E20: 654 | I20: Total | J20: Total | K20: Avg. | L20: Total | M20: Total | N20: Avg. Rent | O20: Avg. Rent
B21: 3 | C21: 311 | D21: 1 | E21: 699 | H21: Bed | I21: Units | J21: SqFt | K21: SqFt | L21: Rent/Mo. | M21: Rent/Yr. | N21: ($ /Unit) | O21: ($ / SqFt)
B22: 4 | C22: 401 | D22: 2 | E22: 868 | H22: 0 | I22: =COUNTIF($D$6:$D$185,$H22) -> 26 | J22: =SUMIF($D$6:$D$185,$H22,E$6:E$185) -> 12349 | K22: =J22/I22 -> 474.96154 | L22: =SUM(L6,L14) -> 74268.333 | M22: =L22*12 -> 891220 | N22: =L22/I22 -> 2856.4744 | O22: =N22/K22*12 -> 72.169406
B23: 4 | C23: 402 | D23: 2 | E23: 646 | H23: 1 | I23: =COUNTIF($D$6:$D$185,$H23) -> 80 | J23: =SUMIF($D$6:$D$185,$H23,E$6:E$185) -> 50068 | K23: =J23/I23 -> 625.85 | L23: =SUM(L7,L15) -> 290184.67 | M23: =L23*12 -> 3482216 | N23: =L23/I23 -> 3627.3083 | O23: =N23/K23*12 -> 69.549732
B24: 4 | C24: 403 | D24: 2 | E24: 800 | H24: 2 | I24: =COUNTIF($D$6:$D$185,$H24) -> 74 | J24: =SUMIF($D$6:$D$185,$H24,E$6:E$185) -> 58099 | K24: =J24/I24 -> 785.12162 | L24: =SUM(L8,L16) -> 349584.08 | M24: =L24*12 -> 4195009 | N24: =L24/I24 -> 4724.1092 | O24: =N24/K24*12 -> 72.204496
B25: 4 | C25: 404 | D25: 1 | E25: 611 | H25: TOTAL / AVG: | I25: =SUM(I22:I24) -> 180 | J25: =SUM(J22:J24) -> 120516 | K25: =J25/I25 -> 669.53333 | L25: =SUM(L22:L24) -> 714037.08 | M25: =SUM(M22:M24) -> 8568445 | N25: =L25/I25 -> 3966.8727 | O25: =N25/K25*12 -> 71.097987
B26: 4 | C26: 405 | D26: 1 | E26: 680
B27: 4 | C27: 406 | D27: 0 | E27: 458
B28: 4 | C28: 407 | D28: 0 | E28: 468
B29: 4 | C29: 408 | D29: 1 | E29: 654
B30: 4 | C30: 409 | D30: 1 | E30: 616
B31: 4 | C31: 410 | D31: 1 | E31: 654
B32: 4 | C32: 411 | D32: 1 | E32: 699
B33: 5 | C33: 501 | D33: 2 | E33: 868
B34: 5 | C34: 502 | D34: 2 | E34: 646
B35: 5 | C35: 503 | D35: 2 | E35: 800
B36: 5 | C36: 504 | D36: 1 | E36: 611
B37: 5 | C37: 505 | D37: 1 | E37: 680
... B185: 21 | C185: 2107 | D185: 2 | E185: 743
B186: TOTAL / AVG: | E186: =SUM(E6:E185) -> 120516

Sheet Development Budget
M2: Development Capitalization | O2: =D88 -> 98550528
M3: Construction Loan Proceeds | N3: 0.75 | O3: 70000000
F4: ZFA | G4: GSF | H4: NSF | M4: Minimum Equity Requirement | N4: =O4/$O$2 -> 0.31393115 | O4: =N4*$O$2 -> 30938080
F5: =Summary!H14 -> 143880 | G5: =Summary!H15 -> 172841.35 | H5: =Summary!H16 -> 137955 | M5: Existing Debt Payoff | O5: 5200000
B7: Acquisition Costs | D7: $ Total Amount | E7: % Total | F7: $ / ZFA | G7: $ / GSF | H7: $ / NSF | I7: Spent to Date | J7: Spent at Closing | K7: Future Funded | M7: SOURCES: | O7: $ Total Amount | P7: % Total | Q7: $ / ZFA | R7: $ / GSF | S7: $ / NSF | T7: Spent to Date | U7: Spent at Closing | V7: Future Funded
B8: Marked-Up Land Value | D8: =F8*$F$5 -> 25179000 | E8: =D8/$D$88 -> 0.2554933 | F8: 175 | G8: =D8/$G$5 -> 145.67695 | H8: =D8/$H$5 -> 182.51604 | I8: =D8 -> 25179000 | J8: 0 | K8: =D8-I8-J8 -> 0 | M8: Senior Loan | O8: =O3 -> 70000000 | P8: =O8/$O$10 -> 0.71029553 | Q8: =O8/$F$5 -> 486.51654 | R8: =O8/$G$5 -> 404.99568 | S8: =O8/$H$5 -> 507.41184 | T8: =O5 -> 5200000 | U8: =U17-U9 -> 0 | V8: =O8-T8-U8 -> 64800000
B9: Total Acquisition Costs | D9: =SUM(D8) -> 25179000 | E9: =D9/$D$88 -> 0.2554933 | F9: =D9/$F$5 -> 175 | G9: =D9/$G$5 -> 145.67695 | H9: =D9/$H$5 -> 182.51604 | I9: =SUM(I8) -> 25179000 | J9: =SUM(J8) -> 0 | K9: =SUM(K8) -> 0 | M9: Sponsor Equity | O9: =O17-O8 -> 28550528 | P9: =O9/$O$10 -> 0.28970447 | Q9: =O9/$F$5 -> 198.43292 | R9: =O9/$G$5 -> 165.18344 | S9: =O9/$H$5 -> 206.95537 | T9: =T17-T8 -> 21979000 | U9: =MIN(O9-T9,U17) -> 3619400 | V9: =O9-T9-U9 -> 2952128
M10: TOTAL SOURCES: | O10: =SUM(O8:O9) -> 98550528 | P10: =O10/$O$10 -> 1 | Q10: =O10/$F$5 -> 684.94946 | R10: =O10/$G$5 -> 570.17912 | S10: =O10/$H$5 -> 714.36721 | T10: =SUM(T8:T9) -> 27179000 | U10: =SUM(U8:U9) -> 3619400 | V10: =SUM(V8:V9) -> 67752128
B11: Hard Costs | D11: $ Total Amount | E11: % Total | F11: $ / ZFA | G11: $ / GSF | H11: $ / NSF | I11: Spent to Date | J11: Spent at Closing | K11: Future Funded | M11: USES: | O11: $ Total Amount | P11: % Total | Q11: $ / ZFA | R11: $ / GSF | S11: $ / NSF | T11: Spent to Date | U11: Spent at Closing | V11: Future Funded
B12: Fencing | D12: 70000 | E12: =D12/$D$88 -> 0.00071029553 | F12: =D12/$F$5 -> 0.48651654 | G12: =D12/$G$5 -> 0.40499568 | H12: =D12/$H$5 -> 0.50741184 | I12: 0 | J12: 0 | K12: =D12-I12-J12 -> 70000 | M12: Acquisition Costs | O12: =D9 -> 25179000 | P12: =O12/$O$17 -> 0.2554933 | Q12: =O12/$F$5 -> 175 | R12: =O12/$G$5 -> 145.67695 | S12: =O12/$H$5 -> 182.51604 | T12: =I9 -> 25179000 | U12: =J9 -> 0 | V12: =O12-T12-U12 -> 0
B13: Demolition | D13: 500000 | E13: =D13/$D$88 -> 0.0050735395 | F13: =D13/$F$5 -> 3.4751182 | G13: =D13/$G$5 -> 2.8928263 | H13: =D13/$H$5 -> 3.6243703 | I13: 0 | J13: 0 | K13: =D13-I13-J13 -> 500000 | M13: Hard Costs | O13: =D65 -> 53742128 | P13: =O13/$O$17 -> 0.54532562 | Q13: =O13/$F$5 -> 373.52049 | R13: =O13/$G$5 -> 310.93328 | S13: =O13/$H$5 -> 389.56274 | T13: =I65 -> 0 | U13: =J65 -> 0 | V13: =O13-T13-U13 -> 53742128
B14: Demo Shed | D14: 50000 | E14: =D14/$D$88 -> 0.00050735395 | F14: =D14/$F$5 -> 0.34751182 | G14: =D14/$G$5 -> 0.28928263 | H14: =D14/$H$5 -> 0.36243703 | I14: 0 | J14: 0 | K14: =D14-I14-J14 -> 50000 | M14: Soft Costs | O14: =D69 -> 6000000 | P14: =O14/$O$17 -> 0.060882474 | Q14: =O14/$F$5 -> 41.701418 | R14: =O14/$G$5 -> 34.713915 | S14: =O14/$H$5 -> 43.492443 | T14: =I69 -> 2000000 | U14: =J69 -> 0 | V14: =O14-T14-U14 -> 4000000
B15: Site Safety Consultant Including OT | D15: 825000 | E15: =D15/$D$88 -> 0.0083713402 | F15: =D15/$F$5 -> 5.733945 | G15: =D15/$G$5 -> 4.7731634 | H15: =D15/$H$5 -> 5.9802109 | I15: 0 | J15: 0 | K15: =D15-I15-J15 -> 825000 | M15: Financing Costs | O15: =D82 -> 3619400 | P15: =O15/$O$17 -> 0.036726338 | Q15: =O15/$F$5 -> 25.155685 | R15: =O15/$G$5 -> 20.940591 | S15: =O15/$H$5 -> 26.236091 | T15: =I82 -> 0 | U15: =J82 -> 3619400 | V15: =O15-T15-U15 -> 0
B16: Site Supervision - Assistant | D16: 240000 | E16: =D16/$D$88 -> 0.002435299 | F16: =D16/$F$5 -> 1.6680567 | G16: =D16/$G$5 -> 1.3885566 | H16: =D16/$H$5 -> 1.7396977 | I16: 0 | J16: 0 | K16: =D16-I16-J16 -> 240000 | M16: Interest/Carry Costs | O16: =D86 -> 10010000 | P16: =O16/$O$17 -> 0.10157226 | Q16: =O16/$F$5 -> 69.571865 | R16: =O16/$G$5 -> 57.914382 | S16: =O16/$H$5 -> 72.559893 | T16: =I86 -> 0 | U16: =J86 -> 0 | V16: =O16-T16-U16 -> 10010000
B17: Monitoring - (Vib, Opt, Crack) | D17: 35000 | E17: =D17/$D$88 -> 0.00035514777 | F17: =D17/$F$5 -> 0.24325827 | G17: =D17/$G$5 -> 0.20249784 | H17: =D17/$H$5 -> 0.25370592 | I17: 0 | J17: 0 | K17: =D17-I17-J17 -> 35000 | M17: TOTAL SOURCES: | O17: =SUM(O12:O16) -> 98550528 | P17: =O17/$O$10 -> 1 | Q17: =O17/$F$5 -> 684.94946 | R17: =O17/$G$5 -> 570.17912 | S17: =O17/$H$5 -> 714.36721 | T17: =SUM(T12:T16) -> 27179000 | U17: =SUM(U12:U16) -> 3619400 | V17: =SUM(V12:V16) -> 67752128
B18: Live Monitoring (security) | D18: 75000 | E18: =D18/$D$88 -> 0.00076103093 | F18: =D18/$F$5 -> 0.52126772 | G18: =D18/$G$5 -> 0.43392394 | H18: =D18/$H$5 -> 0.54365554 | I18: 0 | J18: 0 | K18: =D18-I18-J18 -> 75000
B19: Shop Drawings | D19: 75000 | E19: =D19/$D$88 -> 0.00076103093 | F19: =D19/$F$5 -> 0.52126772 | G19: =D19/$G$5 -> 0.43392394 | H19: =D19/$H$5 -> 0.54365554 | I19: 0 | J19: 0 | K19: =D19-I19-J19 -> 75000
B20: During Construction Cleaning | D20: 800000 | E20: =D20/$D$88 -> 0.0081176633 | F20: =D20/$F$5 -> 5.560189 | G20: =D20/$G$5 -> 4.6285221 | H20: =D20/$H$5 -> 5.7989924 | I20: 0 | J20: 0 | K20: =D20-I20-J20 -> 800000
B21: Scaffolding | D21: 1400000 | E21: =D21/$D$88 -> 0.014205911 | F21: =D21/$F$5 -> 9.7303308 | G21: =D21/$G$5 -> 8.0999136 | H21: =D21/$H$5 -> 10.148237 | I21: 0 | J21: 0 | K21: =D21-I21-J21 -> 1400000
B22: Final Cleaning | D22: 80000 | E22: =D22/$D$88 -> 0.00081176633 | F22: =D22/$F$5 -> 0.5560189 | G22: =D22/$G$5 -> 0.46285221 | H22: =D22/$H$5 -> 0.57989924 | I22: 0 | J22: 0 | K22: =D22-I22-J22 -> 80000
B23: Foundation Waterproofing | D23: 180000 | E23: =D23/$D$88 -> 0.0018264742 | F23: =D23/$F$5 -> 1.2510425 | G23: =D23/$G$5 -> 1.0414175 | H23: =D23/$H$5 -> 1.3047733 | I23: 0 | J23: 0 | K23: =D23-I23-J23 -> 180000
B24: Generator | D24: 183480 | E24: =D24/$D$88 -> 0.0018617861 | F24: =D24/$F$5 -> 1.2752294 | G24: =D24/$G$5 -> 1.0615515 | H24: =D24/$H$5 -> 1.3299989 | I24: 0 | J24: 0 | K24: =D24-I24-J24 -> 183480
B25: SOE/Exc/FO Piles | D25: 1000000 | E25: =D25/$D$88 -> 0.010147079 | F25: =D25/$F$5 -> 6.9502363 | G25: =D25/$G$5 -> 5.7856526 | H25: =D25/$H$5 -> 7.2487405 | I25: 0 | J25: 0 | K25: =D25-I25-J25 -> 1000000
B26: Concrete FO & Structure | D26: 10000000 | E26: =D26/$D$88 -> 0.10147079 | F26: =D26/$F$5 -> 69.502363 | G26: =D26/$G$5 -> 57.856526 | H26: =D26/$H$5 -> 72.487405 | I26: 0 | J26: 0 | K26: =D26-I26-J26 -> 10000000
B27: Water and Sewer | D27: 150000 | E27: =D27/$D$88 -> 0.0015220619 | F27: =D27/$F$5 -> 1.0425354 | G27: =D27/$G$5 -> 0.86784788 | H27: =D27/$H$5 -> 1.0873111 | I27: 0 | J27: 0 | K27: =D27-I27-J27 -> 150000
B28: Soil Removal/Trucking | D28: 800000 | E28: =D28/$D$88 -> 0.0081176633 | F28: =D28/$F$5 -> 5.560189 | G28: =D28/$G$5 -> 4.6285221 | H28: =D28/$H$5 -> 5.7989924 | I28: 0 | J28: 0 | K28: =D28-I28-J28 -> 800000
B29: Elevators | D29: 1600000 | E29: =D29/$D$88 -> 0.016235327 | F29: =D29/$F$5 -> 11.120378 | G29: =D29/$G$5 -> 9.2570441 | H29: =D29/$H$5 -> 11.597985 | I29: 0 | J29: 0 | K29: =D29-I29-J29 -> 1600000
... B63: GC Fee | D63: 1600000 | E63: =D63/$D$88 -> 0.016235327 | F63: =D63/$F$5 -> 11.120378 | G63: =D63/$G$5 -> 9.2570441 | H63: =D63/$H$5 -> 11.597985 | I63: 0 | J63: 0 | K63: =D63-I63-J63 -> 1600000
B64: CONTINGENCY(10%) | C64: 0.1 | D64: =C64*SUM($D$12:$D$63) -> 4885648 | E64: =D64/$D$88 -> 0.049575057 | F64: =D64/$F$5 -> 33.956408 | G64: =D64/$G$5 -> 28.266662 | H64: =D64/$H$5 -> 35.414795 | I64: 0 | J64: 0 | K64: =D64-I64-J64 -> 4885648
B65: Total Hard Costs | D65: =SUM(D12:D64) -> 53742128 | E65: =D65/$D$88 -> 0.54532562 | F65: =D65/$F$5 -> 373.52049 | G65: =D65/$G$5 -> 310.93328 | H65: =D65/$H$5 -> 389.56274 | I65: =SUM(I12:I64) -> 0 | J65: =SUM(J12:J64) -> 0 | K65: =SUM(K12:K64) -> 53742128
B67: Soft Costs | D67: $ Total Amount | E67: % Total | F67: $ / ZFA | G67: $ / GSF | H67: $ / NSF | I67: Spent to Date | J67: Spent at Closing | K67: Future Funded
B68: Soft Costs | D68: 6000000 | E68: =D68/$D$88 -> 0.060882474 | F68: =D68/$F$5 -> 41.701418 | G68: =D68/$G$5 -> 34.713915 | H68: =D68/$H$5 -> 43.492443 | I68: 2000000 | J68: 0 | K68: =D68-I68-J68 -> 4000000
B69: Total Soft Costs | D69: =SUM(D68) -> 6000000 | E69: =D69/$D$88 -> 0.060882474 | F69: =D69/$F$5 -> 41.701418 | G69: =D69/$G$5 -> 34.713915 | H69: =D69/$H$5 -> 43.492443 | I69: =SUM(I68) -> 2000000 | J69: =SUM(J68) -> 0 | K69: =SUM(K68) -> 4000000
B71: Total Unlevered Development Costs | D71: =SUM(D69,D65,D9) -> 84921128 | E71: =D71/$D$88 -> 0.8617014 | F71: =D71/$F$5 -> 590.22191 | G71: =D71/$G$5 -> 491.32414 | H71: =D71/$H$5 -> 615.57122 | I71: =SUM(I69,I65,I9) -> 27179000 | J71: =SUM(J69,J65,J9) -> 0 | K71: =D71-I71-J71 -> 57742128
B73: Financing Costs | D73: $ Total Amount | E73: % Total | F73: $ / ZFA | G73: $ / GSF | H73: $ / NSF | I73: Spent to Date | J73: Spent at Closing | K73: Future Funded
B74: Mortgage Recording Tax | C74: 0.028 | D74: =C74*($O$3-$O$5) -> 1814400 | E74: =D74/$D$88 -> 0.01841086 | F74: =D74/$F$5 -> 12.610509 | G74: =D74/$G$5 -> 10.497488 | H74: =D74/$H$5 -> 13.152115 | I74: 0 | J74: =D74 -> 1814400 | K74: =D74-I74-J74 -> 0
B75: Title | C75: 0.004 | D75: =C75*$O$8 -> 280000 | E75: =D75/$D$88 -> 0.0028411821 | F75: =D75/$F$5 -> 1.9460662 | G75: =D75/$G$5 -> 1.6199827 | H75: =D75/$H$5 -> 2.0296473 | I75: 0 | J75: =D75 -> 280000 | K75: =D75-I75-J75 -> 0
B76: Lender Origination Fee | C76: 0.01 | D76: =C76*$O$8 -> 700000 | E76: =D76/$D$88 -> 0.0071029553 | F76: =D76/$F$5 -> 4.8651654 | G76: =D76/$G$5 -> 4.0499568 | H76: =D76/$H$5 -> 5.0741184 | I76: 0 | J76: =D76 -> 700000 | K76: =D76-I76-J76 -> 0
B77: Mortgage Broker Fee | C77: 0.0075 | D77: =C77*$O$8 -> 525000 | E77: =D77/$D$88 -> 0.0053272165 | F77: =D77/$F$5 -> 3.6488741 | G77: =D77/$G$5 -> 3.0374676 | H77: =D77/$H$5 -> 3.8055888 | I77: 0 | J77: =D77 -> 525000 | K77: =D77-I77-J77 -> 0
B78: Lender Legal | D78: 125000 | E78: =D78/$D$88 -> 0.0012683849 | F78: =D78/$F$5 -> 0.86877954 | G78: =D78/$G$5 -> 0.72320657 | H78: =D78/$H$5 -> 0.90609257 | I78: 0 | J78: =D78 -> 125000 | K78: =D78-I78-J78 -> 0
...

Sheet 421(a) Abatement
B2: Affordable NY - Option C | G2: Residential EGI | H2: =SUM('Proforma I&E'!$F$5:$F$8) -> 8181955.5 | I2: 0.22 | J2: =H2*I2 -> 1800030.2
B3: Borough | E3: Manhattan | G3: Commercial EGI | H3: =SUM('Proforma I&E'!F9:F10) -> 1088232.8 | I3: 0.18 | J3: =H3*I3 -> 195881.9
B4: Block & Lot | E4: 33-35 West 125th Street NY, NY | G4: Total | H4: =SUM(H2:H3) -> 9270188.3 | I4: =J4/H4 -> 0.21530438 | J4: =SUM(J2:J3) -> 1995912.1
B5: AV Prior to Construction | E5: 2089010
B6: Assessment Growth Rate | E6: 0.02
B7: Tax Rate Growth | E7: 0.005
B8: Discount Rate | E8: 0.03
B9: NPV of Tax Savings | E9: =NPV($E$8,$C$25:$AL$25) -> 45664817
B11: Benefit Year | C11: 1 | D11: 2 | E11: 3 | F11: 4 | G11: 5 | H11: 6 | I11: 7 | J11: 8 | K11: 9 | L11: 10 | M11: 11 | N11: 12 | O11: 13 | P11: 14 | Q11: 15 | R11: 16 | S11: 17 | T11: 18 | U11: 19 | V11: 20 | W11: 21 | X11: 22 | Y11: 23 | Z11: 24 | AA11: 25 | AB11: 26 | AC11: 27 | AD11: 28 | AE11: 29 | AF11: 30 | AG11: 31 | AH11: 32 | AI11: 33 | AJ11: 34 | AK11: 35 | AL11: 36
B12: Year of Program (Start) | C12: 46204 | D12: =EDATE(C12,12) -> 46569 | E12: =EDATE(D12,12) -> 46935 | F12: =EDATE(E12,12) -> 47300 | G12: =EDATE(F12,12) -> 47665 | H12: =EDATE(G12,12) -> 48030 | I12: =EDATE(H12,12) -> 48396 | J12: =EDATE(I12,12) -> 48761 | K12: =EDATE(J12,12) -> 49126 | ... AL12: =EDATE(AK12,12) -> 58988
B13: Monthly CF Model Year | C13: =_xlfn.XLOOKUP(C$12,'[2]Monthly CF'!$H$2:$CA$2,'[2]Monthly CF'!$H$4:$CA$4,0) -> 3 | D13: =C13+1 -> 4 | E13: =D13+1 -> 5 | F13: =E13+1 -> 6 | G13: =F13+1 -> 7 | H13: =G13+1 -> 8 | I13: =H13+1 -> 9 | J13: =I13+1 -> 10 | K13: =J13+1 -> 11 | ... AL13: =AK13+1 -> 38
B14: Taxable Assessment | C14: =J4/C21 -> 15967297 | D14: =C14*(1+$E$6) -> 16286643 | E14: =D14*(1+$E$6) -> 16612376 | F14: =E14*(1+$E$6) -> 16944623 | G14: =F14*(1+$E$6) -> 17283516 | H14: =G14*(1+$E$6) -> 17629186 | I14: =H14*(1+$E$6) -> 17981770 | J14: =I14*(1+$E$6) -> 18341405 | K14: =J14*(1+$E$6) -> 18708233 | ... AL14: =AK14*(1+$E$6) -> 31932830
B15: AV Prior to Construction (land assessment) | C15: =E5 -> 2089010 | D15: =$C$15 -> 2089010 | E15: =$C$15 -> 2089010 | F15: =$C$15 -> 2089010 | G15: =$C$15 -> 2089010 | H15: =$C$15 -> 2089010 | I15: =$C$15 -> 2089010 | J15: =$C$15 -> 2089010 | K15: =$C$15 -> 2089010 | ... AL15: =$C$15 -> 2089010
B16: Increase in AV | C16: =C14-C15 -> 13878287 | D16: =D14-D15 -> 14197633 | E16: =E14-E15 -> 14523366 | F16: =F14-F15 -> 14855613 | G16: =G14-G15 -> 15194506 | H16: =H14-H15 -> 15540176 | I16: =I14-I15 -> 15892760 | J16: =J14-J15 -> 16252395 | ... AL16: =AL14-AL15 -> 29843820
B17: % Exempt | C17: 1 | D17: 1 | E17: 1 | F17: 1 | G17: 1 | H17: 1 | I17: 1 | J17: 1 | K17: 1 | L17: 1 | M17: 1 | N17: 1 | O17: 1 | P17: 1 | Q17: 1 | R17: 1 | S17: 1 | T17: 1 | U17: 1 | V17: 1 | W17: 1 | X17: 1 | Y17: 1 | Z17: 1 | AA17: 1 | AB17: 0.3 | AC17: 0.3 | AD17: 0.3 | AE17: 0.3 | AF17: 0.3 | AG17: 0.3 | AH17: 0.3 | AI17: 0.3 | AJ17: 0.3 | AK17: 0.3 | AL17: 0
B18: Exemption Amount | C18: =C16*C17 -> 13878287 | D18: =D16*D17 -> 14197633 | E18: =E16*E17 -> 14523366 | F18: =F16*F17 -> 14855613 | G18: =G16*G17 -> 15194506 | H18: =H16*H17 -> 15540176 | I18: =I16*I17 -> 15892760 | J18: =J16*J17 -> 16252395 | ... AL18: =AL16*AL17 -> 0
B19: Taxable Assessment | C19: =C14-C18 -> 2089010 | D19: =D14-D18 -> 2089010 | E19: =E14-E18 -> 2089010 | F19: =F14-F18 -> 2089010 | G19: =G14-G18 -> 2089010 | H19: =H14-H18 -> 2089010 | I19: =I14-I18 -> 2089010 | J19: =J14-J18 -> 2089010 | ... AL19: =AL14-AL18 -> 31932830
B21: Tax Rate | C21: 0.125 | D21: =C21*(1+$E$7) -> 0.125625 | E21: =D21*(1+$E$7) -> 0.12625312 | F21: =E21*(1+$E$7) -> 0.12688439 | G21: =F21*(1+$E$7) -> 0.12751881 | H21: =G21*(1+$E$7) -> 0.12815641 | I21: =H21*(1+$E$7) -> 0.12879719 | J21: =I21*(1+$E$7) -> 0.12944117 | K21: =J21*(1+$E$7) -> 0.13008838 | ... AL21: =AK21*(1+$E$7) -> 0.14884086
B23: Unabated RET | C23: =C21*C14 -> 1995912.1 | D23: =D21*D14 -> 2046009.5 | E23: =E21*E14 -> 2097364.4 | F23: =F21*F14 -> 2150008.2 | G23: =G21*G14 -> 2203973.4 | H23: =H21*H14 -> 2259293.1 | I23: =I21*I14 -> 2316001.4 | J23: =J21*J14 -> 2374133 | ... AL23: =AL21*AL14 -> 4752910
B24: Abated RET | C24: =C21*C19 -> 261126.25 | D24: =D21*D19 -> 262431.88 | E24: =E21*E19 -> 263744.04 | F24: =F21*F19 -> 265062.76 | G24: =G21*G19 -> 266388.07 | H24: =H21*H19 -> 267720.02 | I24: =I21*I19 -> 269058.62 | J24: =J21*J19 -> 270403.91 | ... AL24: =AL21*AL19 -> 4752910
B25: RET Savings | C25: =C23-C24 -> 1734785.9 | D25: =D23-D24 -> 1783577.6 | E25: =E23-E24 -> 1833620.3 | F25: =F23-F24 -> 1884945.4 | G25: =G23-G24 -> 1937585.3 | H25: =H23-H24 -> 1991573.1 | I25: =I23-I24 -> 2046942.8 | J25: =J23-J24 -> 2103729.1 | ... AL25: =AL23-AL24 -> 0
